<?xml version="1.0"?>
<robot xmlns:xacro="http://www.ros.org/wiki/xacro" name="manipulator">

<xacro:include filename="sixdof_include.xacro" />

<!-- World Link, base_joint -->
<link name="world"></link>

<joint name="base_joint" type="fixed"> 
  <origin xyz="0 0 0" rpy="0 0 0" />
  <parent link="world" />
  <child link="base" />        
</joint>

<!-- Base Link -->
<link name="base">
  <visual>
      <origin xyz="0 0 0.3" rpy="0 0 0" />
      <geometry>
          <cylinder radius="0.1" length="0.6" />
      </geometry>
      <material name="white">
          <color rgba="1 1 1 1" />
      </material>
  </visual>
  <collision>
      <origin xyz="0 0 0.3" rpy="0 0 0" />
      <geometry>
          <cylinder radius="0.1" length="0.6" />
      </geometry>
  </collision>
  <inertial>
      <origin xyz="0 0 0.3" rpy="0 0 0" />
      <mass value="12" />
      <inertia ixx="0.042" ixy="0.0" ixz="0.0" iyy="0.042" iyz="0.0" izz="0.06" />
  </inertial>
</link>

<!-- Joint 1 -->
<joint name="joint_1" type="revolute">
  <parent link="base" />
  <child link="link_1(1)" />
  <origin xyz="0 0 0.6" rpy="0 0 0" />
  <axis xyz="0 0 1" />
  <limit lower="-1.57" upper="4.71" effort="100" velocity="1" />
</joint>

<!-- Link 1 -->
<link name="link_1(1)">
  <visual>
    <origin xyz="0 0 0.05" rpy="0 0 0" />
    <geometry>
      <cylinder radius="0.1" length="0.1" />
    </geometry>
    <material name="orange">
      <color rgba="1 0.3 0.1 1" />
    </material>
  </visual>
  <collision>
    <origin xyz="0 0 0.05" rpy="0 0 0" />
    <geometry>
      <cylinder radius="0.1" length="0.1" />
    </geometry>
  </collision>
  <inertial>
    <origin xyz="0 0 0.05" rpy="0 0 0" />
    <mass value="2" />
    <inertia ixx="0.005" ixy="0.0" ixz="0.0" iyy="0.005" iyz="0.0" izz="0.002" />
  </inertial>
</link>

<joint name="fixed_1" type="fixed"> 
  <origin xyz="0 0 0.1" rpy="-1.57 0 0" />
  <parent link="link_1(1)" />
  <child link="link_1(2)" />        
</joint>

<link name="link_1(2)">
  <visual>
    <origin xyz="0 0 0" rpy="0 0 0" />
    <geometry>
      <cylinder radius="0.1" length="0.4" />
    </geometry>
    <material name="orange">
      <color rgba="1 0.3 0.1 1" />
    </material>
  </visual>
  <collision>
    <origin xyz="0 0 0" rpy="0 0 0" />
    <geometry>
      <cylinder radius="0.1" length="0.4" />
    </geometry>
  </collision>
  <inertial>
    <origin xyz="0 0 0" rpy="0 0 0" />
    <mass value="8" />
    <inertia ixx="0.15" ixy="0.0" ixz="0.0" iyy="0.15" iyz="0.0" izz="0.008" />
  </inertial>
</link>

<!-- Joint 2 -->
<joint name="joint_2" type="revolute">
  <parent link="link_1(2)" />
  <child link="link_2" />
  <origin xyz="0 0 0.2" rpy="0 0 0" />
  <axis xyz="0 0 -1" />
  <limit lower="-4.5" upper="7.64" effort="100" velocity="1" />
</joint>

<!-- Link 2 -->
<link name="link_2">
  <visual>
    <origin xyz="0.2 0 0.05" rpy="0 0 0" />
    <geometry>
        <box size="0.8 0.25 0.1" />      
    </geometry>
    <material name="blue">
      <color rgba="0.2 0.2 1 1" />
    </material>
  </visual>
  <collision>
    <origin xyz="0.2 0 0.05" rpy="0 0 0" />
    <geometry>
        <box size="0.8 0.25 0.1" />
    </geometry>
  </collision>
  <inertial>
    <origin xyz="0.2 0 0.05" rpy="0 0 0" />
    <mass value="12" />
    <inertia ixx="0.87" ixy="0.0" ixz="0.0" iyy="7.74" iyz="0.0" izz="8.49" />
  </inertial>
</link>

<!-- Joint 3 -->
<joint name="joint_3" type="revolute">
  <parent link="link_2" />
  <child link="link_3" />
  <origin xyz="0.5 0 0" rpy="0 0 0" />
  <axis xyz="0 0 1" />
  <limit lower="0" upper="6.28" effort="100" velocity="1" />
</joint>

<!-- Link 3 -->
<link name="link_3">
  <visual>
    <origin xyz="0 0.15 -0.05" rpy="0 0 0" />
    <geometry>
        <box size="0.2 0.5 0.1" />
    </geometry>
    <material name="orange">
      <color rgba="1 0.3 0.1 1" />
    </material>
  </visual>
  <collision>
    <origin xyz="0 0.15 -0.05" rpy="0 0 0" />
    <geometry>
        <box size="0.2 0.5 0.1" />
    </geometry>
  </collision>
  <inertial>
    <origin xyz="0 0.15 -0.05" rpy="0 0 0" />
    <mass value="8" />
    <inertia ixx="0.207" ixy="0.0" ixz="0.0" iyy="0.033" iyz="0.0" izz="0.233" />
  </inertial>
</link>

<!-- Joint 4 -->
<joint name="joint_4" type="revolute">
  <parent link="link_3" />
  <child link="link_4" />
  <origin xyz="0 0.4 -0.05" rpy="-1.57 0 0" />
  <axis xyz="0 0 -1" />
  <limit lower="0" upper="6.28" effort="100" velocity="1" />
</joint>

<!-- Link 4 -->
<link name="link_4">
  <visual>
    <origin xyz="0 0 0.025" rpy="0 0 0" />
    <geometry>
        <cylinder radius="0.1" length="0.05" />
    </geometry>
    <material name="blue">
      <color rgba="0.2 0.2 1 1" />
    </material>
  </visual>
  <collision>
    <origin xyz="0 0 0.025" rpy="0 0 0" />
    <geometry>
      <cylinder radius="0.1" length="0.05" />
    </geometry>
  </collision>
  <inertial>
    <origin xyz="0 0 0.025" rpy="0 0 0" />
    <mass value="2" />
    <inertia ixx="0.207" ixy="0.0" ixz="0.0" iyy="0.033" iyz="0.0" izz="0.233" />
  </inertial>
</link>











<xacro:include filename="sixdof_gazebo.xacro" />

</robot>